Mon, 04 Apr 2022 00:25:21 log.py[line:230] ERROR Internal Server Error: /register/
Traceback (most recent call last):
  File "/Library/Frameworks/Python.framework/Versions/3.7/lib/python3.7/site-packages/django/core/handlers/exception.py", line 47, in inner
    response = get_response(request)
  File "/Library/Frameworks/Python.framework/Versions/3.7/lib/python3.7/site-packages/django/core/handlers/base.py", line 181, in _get_response
    response = wrapped_callback(request, *callback_args, **callback_kwargs)
  File "/Users/bytedance/PycharmProjects/djangoProject/mysite/tracer/views/account.py", line 41, in register
    if form.is_valid():
  File "/Library/Frameworks/Python.framework/Versions/3.7/lib/python3.7/site-packages/django/forms/forms.py", line 175, in is_valid
    return self.is_bound and not self.errors
  File "/Library/Frameworks/Python.framework/Versions/3.7/lib/python3.7/site-packages/django/forms/forms.py", line 170, in errors
    self.full_clean()
  File "/Library/Frameworks/Python.framework/Versions/3.7/lib/python3.7/site-packages/django/forms/forms.py", line 373, in full_clean
    self._clean_form()
  File "/Library/Frameworks/Python.framework/Versions/3.7/lib/python3.7/site-packages/django/forms/forms.py", line 400, in _clean_form
    cleaned_data = self.clean()
  File "/Users/bytedance/PycharmProjects/djangoProject/mysite/tracer/form/account.py", line 71, in clean
    user = self.cleaned_data['user']
KeyError: 'user'
Mon, 04 Apr 2022 00:25:33 log.py[line:230] ERROR Internal Server Error: /register/
Traceback (most recent call last):
  File "/Library/Frameworks/Python.framework/Versions/3.7/lib/python3.7/site-packages/django/core/handlers/exception.py", line 47, in inner
    response = get_response(request)
  File "/Library/Frameworks/Python.framework/Versions/3.7/lib/python3.7/site-packages/django/core/handlers/base.py", line 181, in _get_response
    response = wrapped_callback(request, *callback_args, **callback_kwargs)
  File "/Users/bytedance/PycharmProjects/djangoProject/mysite/tracer/views/account.py", line 41, in register
    if form.is_valid():
  File "/Library/Frameworks/Python.framework/Versions/3.7/lib/python3.7/site-packages/django/forms/forms.py", line 175, in is_valid
    return self.is_bound and not self.errors
  File "/Library/Frameworks/Python.framework/Versions/3.7/lib/python3.7/site-packages/django/forms/forms.py", line 170, in errors
    self.full_clean()
  File "/Library/Frameworks/Python.framework/Versions/3.7/lib/python3.7/site-packages/django/forms/forms.py", line 373, in full_clean
    self._clean_form()
  File "/Library/Frameworks/Python.framework/Versions/3.7/lib/python3.7/site-packages/django/forms/forms.py", line 400, in _clean_form
    cleaned_data = self.clean()
  File "/Users/bytedance/PycharmProjects/djangoProject/mysite/tracer/form/account.py", line 71, in clean
    user = self.cleaned_data['user']
KeyError: 'user'
